<?xml version="1.0" encoding="utf-8"?>
<robot name="leader_right" xmlns:xacro="http://ros.org/wiki/xacro">
  <link name="base_link">
    <inertial>
      <origin
        xyz="5.199e-05 -0.03429087 5.295e-05"
        rpy="0 0 0" />
      <mass
        value="0.37290125" />
      <inertia
        ixx="0.00034804"
        ixy="-3.9e-07"
        ixz="-3e-08"
        iyy="0.00014057"
        iyz="-8e-07"
        izz="0.00034074" />
    </inertial>
    <visual>
      <origin
        xyz="0 0 0"
        rpy="0 0 0" />
      <geometry>
        <mesh
          filename="package://trossen_arm_description/meshes/leader_right/base_link.stl" />
      </geometry>
      <material
        name="">
        <color
          rgba="0.752941176470588 0.752941176470588 0.752941176470588 1" />
      </material>
    </visual>
    <collision>
      <origin
        xyz="0 0 0"
        rpy="0 0 0" />
      <geometry>
        <mesh
          filename="package://trossen_arm_description/meshes/leader_right/base_link.stl" />
      </geometry>
    </collision>
  </link>
  <link name="link_1">
    <inertial>
      <origin
        xyz="0.00331378 -0.03460068 -4.285e-05"
        rpy="0 0 0" />
      <mass
        value="0.4523603" />
      <inertia
        ixx="0.0001893"
        ixy="3.6e-06"
        ixz="-3.3e-07"
        iyy="0.00043171"
        iyz="0.0"
        izz="0.00045089" />
    </inertial>
    <visual>
      <origin
        xyz="0 0 0"
        rpy="0 0 0" />
      <geometry>
        <mesh
          filename="package://trossen_arm_description/meshes/leader_right/link_1.stl" />
      </geometry>
      <material
        name="">
        <color
          rgba="0.752941176470588 0.752941176470588 0.752941176470588 1" />
      </material>
    </visual>
    <collision>
      <origin
        xyz="0 0 0"
        rpy="0 0 0" />
      <geometry>
        <mesh
          filename="package://trossen_arm_description/meshes/leader_right/link_1.stl" />
      </geometry>
    </collision>
  </link>
  <joint name="joint_0" type="revolute">
    <origin
      xyz="0 -0.05825 0"
      rpy="0 0 0" />
    <parent link="base_link" />
    <child link="link_1" />
    <axis xyz="0 -1 0" />
    <limit
      effort="0"
      lower="${-pi / 2}"
      upper="${pi}"
      velocity="${2 * pi}" />
  </joint>
  <link name="link_2">
    <inertial>
      <origin
        xyz="-5.27e-06 1.239e-05 -0.08091014"
        rpy="0 0 0" />
      <mass
        value="0.33783172" />
      <inertia
        ixx="0.00031788"
        ixy="4e-08"
        ixz="-4.9e-07"
        iyy="0.00034942"
        iyz="-4.5e-07"
        izz="0.00016037" />
    </inertial>
    <visual>
      <origin
        xyz="0 0 0"
        rpy="0 0 0" />
      <geometry>
        <mesh
          filename="package://trossen_arm_description/meshes/leader_right/link_2.stl" />
      </geometry>
      <material
        name="">
        <color
          rgba="0.752941176470588 0.752941176470588 0.752941176470588 1" />
      </material>
    </visual>
    <collision>
      <origin
        xyz="0 0 0"
        rpy="0 0 0" />
      <geometry>
        <mesh
          filename="package://trossen_arm_description/meshes/leader_right/link_2.stl" />
      </geometry>
    </collision>
  </link>
  <joint name="joint_1" type="revolute">
    <origin
      xyz="0 -0.0365 0"
      rpy="0 0 0" />
    <parent link="link_1" />
    <child link="link_2" />
    <axis xyz="1 0 0" />
    <limit
      effort="0"
      lower="${-pi}"
      upper="0"
      velocity="${2 * pi}" />
  </joint>
  <link name="link_3">
    <inertial>
      <origin
        xyz="0.01706827 0.00212153 -0.1667902"
        rpy="0 0 0" />
      <mass
        value="0.46940642" />
      <inertia
        ixx="0.00182642"
        ixy="-3.41e-06"
        ixz="0.00015666"
        iyy="0.00165644"
        iyz="2.673e-05"
        izz="0.00039819" />
    </inertial>
    <visual>
      <origin
        xyz="0 0 0"
        rpy="0 0 0" />
      <geometry>
        <mesh
          filename="package://trossen_arm_description/meshes/leader_right/link_3.stl" />
      </geometry>
      <material
        name="">
        <color
          rgba="0.752941176470588 0.752941176470588 0.752941176470588 1" />
      </material>
    </visual>
    <collision>
      <origin
        xyz="0 0 0"
        rpy="0 0 0" />
      <geometry>
        <mesh
          filename="package://trossen_arm_description/meshes/leader_right/link_3.stl" />
      </geometry>
    </collision>
  </link>
  <joint name="joint_2" type="revolute">
    <origin
      xyz="0 0 -0.106"
      rpy="0 0 0" />
    <parent link="link_2" />
    <child link="link_3" />
    <axis xyz="0 0 -1" />
    <limit
      effort="0"
      lower="${-pi / 2}"
      upper="${pi / 2}"
      velocity="${2 * pi}" />
  </joint>
  <link name="link_4">
    <inertial>
      <origin
        xyz="-0.01912502 2.771e-05 -0.0899419"
        rpy="0 0 0" />
      <mass
        value="0.19153172" />
      <inertia
        ixx="0.00019027"
        ixy="-1e-07"
        ixz="-1.489e-05"
        iyy="0.00015938"
        iyz="-4.7e-07"
        izz="8.565e-05" />
    </inertial>
    <visual>
      <origin
        xyz="0 0 0"
        rpy="0 0 0" />
      <geometry>
        <mesh
          filename="package://trossen_arm_description/meshes/leader_right/link_4.stl" />
      </geometry>
      <material
        name="">
        <color
          rgba="0.752941176470588 0.752941176470588 0.752941176470588 1" />
      </material>
    </visual>
    <collision>
      <origin
        xyz="0 0 0"
        rpy="0 0 0" />
      <geometry>
        <mesh
          filename="package://trossen_arm_description/meshes/leader_right/link_4.stl" />
      </geometry>
    </collision>
  </link>
  <joint name="joint_3" type="revolute">
    <origin
      xyz="0.02 0 -0.1938"
      rpy="0 0 0" />
    <parent link="link_3" />
    <child link="link_4" />
    <!-- <axis xyz="0 1 0" /> -->
    <axis xyz="0 -1 0" />
    <limit
      effort="0"
      lower="0"
      upper="${3 * pi / 4}"
      velocity="${2 * pi}" />
  </joint>
  <link name="link_5">
    <inertial>
      <origin
        xyz="-0.00025767 0.00302328 -0.03375968"
        rpy="0 0 0" />
      <mass
        value="0.24163171" />
      <inertia
        ixx="0.00022638"
        ixy="1e-06"
        ixz="-4.42e-06"
        iyy="0.00016124"
        iyz="7.25e-06"
        izz="0.00013726" />
    </inertial>
    <visual>
      <origin
        xyz="0 0 0"
        rpy="0 0 0" />
      <geometry>
        <mesh
          filename="package://trossen_arm_description/meshes/leader_right/link_5.stl" />
      </geometry>
      <material
        name="">
        <color
          rgba="0.752941176470588 0.752941176470588 0.752941176470588 1" />
      </material>
    </visual>
    <collision>
      <origin
        xyz="0 0 0"
        rpy="0 0 0" />
      <geometry>
        <mesh
          filename="package://trossen_arm_description/meshes/leader_right/link_5.stl" />
      </geometry>
    </collision>
  </link>
  <joint name="joint_4" type="revolute">
    <origin
      xyz="-0.02 0 -0.1185"
      rpy="0 0 0" />
    <parent link="link_4" />
    <child link="link_5" />
    <axis xyz="0 0 -1" />
    <limit
      effort="0"
      lower="${-pi / 2}"
      upper="${pi / 2}"
      velocity="${2 * pi}" />
  </joint>
  <link name="link_6">
    <inertial>
      <origin
        xyz="-0.01044529 9.1e-06 0.00011242"
        rpy="0 0 0" />
      <mass
        value="0.18731697" />
      <inertia
        ixx="6.195e-05"
        ixy="-1e-08"
        ixz="-3.2e-07"
        iyy="5.051e-05"
        iyz="0.0"
        izz="6.44e-05" />
    </inertial>
    <visual>
      <origin
        xyz="0 0 0"
        rpy="0 0 0" />
      <geometry>
        <mesh
          filename="package://trossen_arm_description/meshes/leader_right/link_6.stl" />
      </geometry>
      <material
        name="">
        <color
          rgba="0.752941176470588 0.752941176470588 0.752941176470588 1" />
      </material>
    </visual>
    <collision>
      <origin
        xyz="0 0 0"
        rpy="0 0 0" />
      <geometry>
        <mesh
          filename="package://trossen_arm_description/meshes/leader_right/link_6.stl" />
      </geometry>
    </collision>
  </link>
  <joint name="joint_5" type="revolute">
    <origin
      xyz="0 0 -0.101"
      rpy="0 0 0" />
    <parent link="link_5" />
    <child link="link_6" />
    <axis xyz="0 1 0" />
    <limit
      effort="0"
      lower="${-pi / 4}"
      upper="${pi / 4}"
      velocity="${2 * pi}" />
  </joint>
  <link name="end_link">
    <inertial>
      <origin
        xyz="-0.01502064 0.00191435 0.00656522"
        rpy="0 0 0" />
      <mass
        value="0.00915397" />
      <inertia
        ixx="1.2e-06"
        ixy="-2.1e-07"
        ixz="1.02e-06"
        iyy="3.85e-06"
        iyz="1.1e-07"
        izz="2.84e-06" />
    </inertial>
    <visual>
      <origin
        xyz="0 0 0"
        rpy="0 0 0" />
      <geometry>
        <mesh
          filename="package://trossen_arm_description/meshes/leader_right/end_link.stl" />
      </geometry>
      <material
        name="">
        <color
          rgba="0.752941176470588 0.752941176470588 0.752941176470588 1" />
      </material>
    </visual>
    <collision>
      <origin
        xyz="0 0 0"
        rpy="0 0 0" />
      <geometry>
        <mesh
          filename="package://trossen_arm_description/meshes/leader_right/end_link.stl" />
      </geometry>
    </collision>
  </link>
  <joint name="joint_6" type="revolute">
    <origin
      xyz="-0.034 0 0"
      rpy="0 0 0" />
    <parent link="link_6" />
    <child link="end_link" />
    <axis xyz="-1 0 0" />
    <!-- <axis xyz="1 0 0" /> -->
    <limit
      effort="0"
      lower="${-pi / 2}"
      upper="${pi / 2}"
      velocity="${2 * pi}" />
  </joint>
</robot>
