<?xml version="1.0" encoding="utf-8"?>
<robot name="leader_left" xmlns:xacro="http://ros.org/wiki/xacro">
  <link name="base_link">
    <!-- <inertial>
      <origin
        xyz="-1.39153798077853E-08 0.0294562601114362 -7.37998769182226E-05"
        rpy="0 0 0" />
      <mass value="0.139112019601077" />
      <inertia
        ixx="5.49621467906338E-05"
        ixy="-1.28792782126173E-12"
        ixz="2.72711813446347E-12"
        iyy="6.23808866721586E-05"
        iyz="-8.11487720040051E-09"
        izz="4.83929577561353E-05" />
    </inertial> -->
    <visual>
      <origin
        xyz="0 0 0"
        rpy="0 0 0" />
      <geometry>
        <mesh filename="package://trossen_arm_description/meshes/leader_left/base_link.stl" />
      </geometry>
      <material
        name="">
        <color
          rgba="0.752941176470588 0.752941176470588 0.752941176470588 1" />
      </material>
    </visual>
    <collision>
      <origin
        xyz="0 0 0"
        rpy="0 0 0" />
      <geometry>
        <mesh filename="package://trossen_arm_description/meshes/leader_left/base_link.stl" />
      </geometry>
    </collision>
  </link>
  <link name="link_1">
    <!-- <inertial>
      <origin
        xyz="0.00167418624532228 0.0312005017303284 9.84503703002868E-09"
        rpy="0 0 0" />
      <mass value="0.191701342033879" />
      <inertia
        ixx="7.94635277133711E-05"
        ixy="6.77210601032393E-09"
        ixz="1.29027652006086E-12"
        iyy="7.05878952700333E-05"
        iyz="2.37542083271049E-12"
        izz="6.45361069374152E-05" />
    </inertial> -->
    <visual>
      <origin
        xyz="0 0 0"
        rpy="0 0 0" />
      <geometry>
        <mesh filename="package://trossen_arm_description/meshes/leader_left/link_1.stl" />
      </geometry>
      <material
        name="">
        <color
          rgba="0.752941176470588 0.752941176470588 0.752941176470588 1" />
      </material>
    </visual>
    <collision>
      <origin
        xyz="0 0 0"
        rpy="0 0 0" />
      <geometry>
        <mesh filename="package://trossen_arm_description/meshes/leader_left/link_1.stl" />
      </geometry>
    </collision>
  </link>
  <joint name="joint_0" type="revolute">
    <origin
      xyz="0 0.05825 0"
      rpy="0 0 0" />
    <parent link="base_link" />
    <child link="link_1" />
    <axis xyz="0 1 0" />
    <limit
      effort="0"
      lower="${-pi}"
      upper="${pi / 2}"
      velocity="${2 * pi}" />
  </joint>
  <link name="link_2">
    <!-- <inertial>
      <origin
        xyz="-5.36604041963485E-07 -5.50461221995174E-05 -0.0631252939943119"
        rpy="0 0 0" />
      <mass value="0.0968334812201936" />
      <inertia
        ixx="2.42097049366524E-05"
        ixy="-3.20732392595137E-10"
        ixz="-5.48554273025445E-11"
        iyy="2.77810926752734E-05"
        iyz="-7.97672204227387E-09"
        izz="2.76652157252568E-05" />
    </inertial> -->
    <visual>
      <origin
        xyz="0 0 0"
        rpy="0 0 0" />
      <geometry>
        <mesh filename="package://trossen_arm_description/meshes/leader_left/link_2.stl" />
      </geometry>
      <material
        name="">
        <color
          rgba="0.752941176470588 0.752941176470588 0.752941176470588 1" />
      </material>
    </visual>
    <collision>
      <origin
        xyz="0 0 0"
        rpy="0 0 0" />
      <geometry>
        <mesh filename="package://trossen_arm_description/meshes/leader_left/link_2.stl" />
      </geometry>
    </collision>
  </link>
  <joint name="joint_1" type="revolute">
    <origin
      xyz="0 0.0365 0"
      rpy="0 0 0" />
    <parent link="link_1" />
    <child link="link_2" />
    <axis xyz="1 0 0" />
    <limit
      effort="0"
      lower="0"
      upper="${pi}"
      velocity="${2 * pi}" />
  </joint>
  <link name="link_3">
    <!-- <inertial>
      <origin
        xyz="0.0139862989493807 -0.000307663140594786 -0.143995683793506"
        rpy="0 0 0" />
      <mass value="0.260115273188126" />
      <inertia
        ixx="0.000427379966789233"
        ixy="7.81663177406395E-09"
        ixz="-3.77410479277309E-05"
        iyy="0.000462804238440482"
        iyz="3.2468971330732E-12"
        izz="7.59010644840441E-05" />
    </inertial> -->
    <visual>
      <origin
        xyz="0 0 0"
        rpy="0 0 0" />
      <geometry>
        <mesh filename="package://trossen_arm_description/meshes/leader_left/link_3.stl" />
      </geometry>
      <material
        name="">
        <color
          rgba="0.752941176470588 0.752941176470588 0.752941176470588 1" />
      </material>
    </visual>
    <collision>
      <origin
        xyz="0 0 0"
        rpy="0 0 0" />
      <geometry>
        <mesh filename="package://trossen_arm_description/meshes/leader_left/link_3.stl" />
      </geometry>
    </collision>
  </link>
  <joint name="joint_2" type="revolute">
    <origin
      xyz="0 0 -0.0979"
      rpy="0 0 0" />
    <parent link="link_2" />
    <child link="link_3" />
    <axis xyz="0 0 -1" />
    <limit
      effort="0"
      lower="${-pi / 2}"
      upper="${pi / 2}"
      velocity="${2 * pi}" />
  </joint>
  <link name="link_4">
    <!-- <inertial>
      <origin
        xyz="-0.0172302461757324 -0.00148804054743533 -0.0737933680183248"
        rpy="0 0 0" />
      <mass value="0.108911932357874" />
      <inertia
        ixx="3.67350299124522E-05"
        ixy="-3.20693526496353E-10"
        ixz="4.67937259825551E-06"
        iyy="3.79435353491666E-05"
        iyz="-5.4952014279273E-11"
        izz="2.79681494421084E-05" />
    </inertial> -->
    <visual>
      <origin
        xyz="0 0 0"
        rpy="0 0 0" />
      <geometry>
        <mesh filename="package://trossen_arm_description/meshes/leader_left/link_4.stl" />
      </geometry>
      <material
        name="">
        <color
          rgba="0.752941176470588 0.752941176470588 0.752941176470588 1" />
      </material>
    </visual>
    <collision>
      <origin
        xyz="0 0 0"
        rpy="0 0 0" />
      <geometry>
        <mesh filename="package://trossen_arm_description/meshes/leader_left/link_4.stl" />
      </geometry>
    </collision>
  </link>
  <joint name="joint_3" type="revolute">
    <origin
      xyz="0.02 0 -0.2019"
      rpy="0 0 0" />
    <parent link="link_3" />
    <child link="link_4" />
    <axis xyz="0 1 0" />
    <limit
      effort="0"
      lower="${-3 * pi / 4}"
      upper="0"
      velocity="${2 * pi}" />
  </joint>
  <link name="link_5">
    <!-- <inertial>
      <origin
        xyz="5.49453074869539E-05 -0.00190317175179952 -0.0327138325209553"
        rpy="0 0 0" />
      <mass value="0.172855880218874" />
      <inertia
        ixx="8.34719229858291E-05"
        ixy="-5.90058481141441E-07"
        ixz="1.67532786136818E-06"
        iyy="9.21933396956858E-05"
        iyz="2.6519343260011E-06"
        izz="4.30956747309204E-05" />
    </inertial> -->
    <visual>
      <origin
        xyz="0 0 0"
        rpy="0 0 0" />
      <geometry>
        <mesh filename="package://trossen_arm_description/meshes/leader_left/link_5.stl" />
      </geometry>
      <material
        name="">
        <color
          rgba="0.752941176470588 0.752941176470588 0.752941176470588 1" />
      </material>
    </visual>
    <collision>
      <origin
        xyz="0 0 0"
        rpy="0 0 0" />
      <geometry>
        <mesh filename="package://trossen_arm_description/meshes/leader_left/link_5.stl" />
      </geometry>
    </collision>
  </link>
  <joint name="joint_4" type="revolute">
    <origin
      xyz="-0.02 0 -0.1185"
      rpy="0 0 0" />
    <parent link="link_4" />
    <child link="link_5" />
    <axis xyz="0 0 -1" />
    <limit
      effort="0"
      lower="${-pi / 2}"
      upper="${pi / 2}"
      velocity="${2 * pi}" />
  </joint>
  <link name="link_6">
    <!-- <inertial>
      <origin
        xyz="-0.00808258410436389 -1.55757918357396E-05 -5.258245473172E-05"
        rpy="0 0 0" />
      <mass value="0.0945457994340804" />
      <inertia
        ixx="2.28857807728819E-05"
        ixy="-4.1841128650511E-09"
        ixz="-1.40165275583681E-08"
        iyy="1.66489373164975E-05"
        iyz="-1.123126180633E-09"
        izz="1.71149397185573E-05" />
    </inertial> -->
    <visual>
      <origin
        xyz="0 0 0"
        rpy="0 0 0" />
      <geometry>
        <mesh filename="package://trossen_arm_description/meshes/leader_left/link_6.stl" />
      </geometry>
      <material
        name="">
        <color
          rgba="0.752941176470588 0.752941176470588 0.752941176470588 1" />
      </material>
    </visual>
    <collision>
      <origin
        xyz="0 0 0"
        rpy="0 0 0" />
      <geometry>
        <mesh filename="package://trossen_arm_description/meshes/leader_left/link_6.stl" />
      </geometry>
    </collision>
  </link>
  <joint name="joint_5" type="revolute">
    <origin
      xyz="0 0 -0.101"
      rpy="3.1416 0 0" />
    <parent link="link_5" />
    <child link="link_6" />
    <axis xyz="0 1 0" />
    <limit
      effort="0"
      lower="${-pi / 4}"
      upper="${pi / 4}"
      velocity="${2 * pi}" />
  </joint>
  <link name="end_link">
    <!-- <inertial>
      <origin
        xyz="-0.0532965871728044 8.96532655059179E-09 -0.0694281601388372"
        rpy="0 0 0" />
      <mass value="0.0949576109060716" />
      <inertia
        ixx="3.84221007642208E-05"
        ixy="3.20422759772033E-11"
        ixz="2.68672960859202E-05"
        iyy="0.000163776489114621"
        iyz="4.23116882460614E-12"
        izz="0.000136448375290933" />
    </inertial> -->
    <visual>
      <origin
        xyz="0 0 0"
        rpy="0 0 0" />
      <geometry>
        <mesh filename="package://trossen_arm_description/meshes/leader_left/end_link.stl" />
      </geometry>
      <material
        name="">
        <color
          rgba="0.752941176470588 0.752941176470588 0.752941176470588 1" />
      </material>
    </visual>
    <collision>
      <origin
        xyz="0 0 0"
        rpy="0 0 0" />
      <geometry>
        <mesh filename="package://trossen_arm_description/meshes/leader_left/end_link.stl" />
      </geometry>
    </collision>
  </link>
  <joint name="joint_6" type="revolute">
    <origin
      xyz="-0.034 0 0"
      rpy="3.1416 0 0" />
    <parent link="link_6" />
    <child link="end_link" />
    <axis xyz="1 0 0" />
    <limit
      effort="0"
      lower="${-pi / 2}"
      upper="${pi / 2}"
      velocity="${2 * pi}" />
  </joint>
</robot>
